Workbook

Sheet Memória Cálculo E-Sol
A1: Projeto | B1: Cliente | C1: Obra paga | D1: Data Término | E1: Mês Pagamento | F1: Qtd Módulos | G1: Potência Módulos | H1: Potência Usina (kWp) | I1: Valor por Obra (R$) | J1: Nota da Obra | K1: Prejuízo/Remoção da Premiação | L1: Valor corrigido por obra (R$) | M1: Elivelton (P) | N1: Fábio (P) | O1: Moisés (P) | P1: Gabriel T. (P) | Q1: Gabriel M. (P) | R1: Hyan (P) | S1: Gustavo G. (P) | T1: Kauã (P) | U1: Gustavo P. (P) | V1: Enderson (P) | W1: Flávio (P) | X1: Ley (P) | Y1: Élder (P) | Z1: Material (P) | AA1: Projeto (P) | AB1: Nº de Participantes | AC1: Elivelton (DP) | AD1: Fábio (DP) | AE1: Moisés (DP) | AF1: Gabriel T. (DP) | AG1: Gabriel M. (DP) | AH1: Hyan (DP) | AI1: Gustavo G. (DP) | AJ1: Kauã (DP) | AK1: Gustavo P. (DP) | AL1: Enderson (DP) | AM1: Flávio (DP) | AN1: Ley (DP) | AO1: Élder (DP) | AP1: Material (DP) | AQ1: Projeto (DP) | AR1: Soma dos Pesos | AS1: Média Ponderada | AT1: Elivelton (360) | AU1: Fábio (360) | AV1: Moisés (360) | AW1: Gabriel T. (360) | AX1: Gabriel M. (360) | AY1: Hyan (360) | AZ1: Gustavo G. (360) | BA1: Kauã (360) | BB1: Gustavo P. (360) | BC1: Enderson (360) | BD1: Flávio 360) | BE1: Ley (360) | BF1: Élder (360) | BG1: Material (360) | BH1: Projeto (360) | BI1: Elivelton (R$) | BJ1: Fábio (R$) | BK1: Moisés (R$) | BL1: Gabriel T. (R$) | BM1: Gabriel M. (R$) | BN1: Hyan (R$) | BO1: Gustavo G. (R$) | BP1: Kauã (R$) | BQ1: Gustavo P. (R$) | BR1: Enderson (R$) | BS1: Flávio (R$) | BT1: Ley (R$) | BU1: Élder (R$) | BV1: Material (R$) | BW1: Projeto (R$) | BX1: Valor Final por obra (R$) | BY1: Elivelton (Fq) | BZ1: Fábio (Fq) | CA1: Moisés (Fq) | CB1: Gabriel T. (Fq) | CC1: Gabriel M. (Fq) | CD1: Hyan (Fq) | CE1: Gustavo G. (Fq) | CF1: Kauã (Fq) | CG1: Gustavo P. (Fq) | CH1: Enderson (Fq) | CI1: Flávio (Fq) | CJ1: Ley (Fq) | CK1: Élder (Fq) | CL1: Material (Fq) | CM1: Projeto (Fq)
A2: =IFERROR(__xludf.DUMMYFUNCTION("IMPORTRANGE(""1JVgAmMknpUlV7MHy1kkNJsmHnDibvSzHA2wp265bu2I"",""Notas!A4:A999"")"),"P774") -> P774 | B2: =IFERROR(__xludf.DUMMYFUNCTION("IMPORTRANGE(""1JVgAmMknpUlV7MHy1kkNJsmHnDibvSzHA2wp265bu2I"",""Notas!B4:B999"")"),"João Luiz Gonzaga") -> João Luiz Gonzaga | C2: x | D2: =IFERROR(__xludf.DUMMYFUNCTION("IMPORTRANGE(""1JVgAmMknpUlV7MHy1kkNJsmHnDibvSzHA2wp265bu2I"",""Notas!D4:D999"")"),45674) -> 45674 | E2: =IF(ISBLANK(D2),"",TEXT(D2,"MMMM")) -> janeiro | F2: =IFERROR(__xludf.DUMMYFUNCTION("IMPORTRANGE(""1JVgAmMknpUlV7MHy1kkNJsmHnDibvSzHA2wp265bu2I"",""Notas!E4:E999"")"),14) -> 14 | G2: =IFERROR(__xludf.DUMMYFUNCTION("IMPORTRANGE(""1JVgAmMknpUlV7MHy1kkNJsmHnDibvSzHA2wp265bu2I"",""Notas!F4:F999"")"),600) -> 600 | H2: =IF(ISBLANK(G2),"",F2*G2/1000) -> 8.4 | I2: =IF(ISBLANK(F2),"",IF(H2<5,200,IF(H2<10,300,IF(H2<20,500,IF(H2<30,750,IF(H2<50,1000,IF(H2<75,1500,IF(H2>75,2000)))))))) -> 300 | J2: =IFERROR(__xludf.DUMMYFUNCTION("IMPORTRANGE(""1JVgAmMknpUlV7MHy1kkNJsmHnDibvSzHA2wp265bu2I"", ""Notas!AI4:AI999"")"),86.2222222222222) -> 86.222222 | K2: FALSE | L2: =IF(K2=TRUE(),0,IF(C2="x",IF(ISBLANK(A2),"", I2*(J2/100)),"PENDENTE")) -> 258.66667 | M2: =IFERROR(__xludf.DUMMYFUNCTION("IMPORTRANGE(""1JVgAmMknpUlV7MHy1kkNJsmHnDibvSzHA2wp265bu2I"",""Notas!AL4:AL999"")"),"") | N2: =IFERROR(__xludf.DUMMYFUNCTION("IMPORTRANGE(""1JVgAmMknpUlV7MHy1kkNJsmHnDibvSzHA2wp265bu2I"",""Notas!AM4:AM999"")"),"") | O2: =IFERROR(__xludf.DUMMYFUNCTION("IMPORTRANGE(""1JVgAmMknpUlV7MHy1kkNJsmHnDibvSzHA2wp265bu2I"",""Notas!AN4:AN999"")"),"x") -> x | P2: =IFERROR(__xludf.DUMMYFUNCTION("IMPORTRANGE(""1JVgAmMknpUlV7MHy1kkNJsmHnDibvSzHA2wp265bu2I"",""Notas!AO4:AO999"")"),"x") -> x | Q2: =IFERROR(__xludf.DUMMYFUNCTION("IMPORTRANGE(""1JVgAmMknpUlV7MHy1kkNJsmHnDibvSzHA2wp265bu2I"",""Notas!AP4:AP999"")"),"") | R2: =IFERROR(__xludf.DUMMYFUNCTION("IMPORTRANGE(""1JVgAmMknpUlV7MHy1kkNJsmHnDibvSzHA2wp265bu2I"",""Notas!AQ4:AQ999"")"),"") | S2: =IFERROR(__xludf.DUMMYFUNCTION("IMPORTRANGE(""1JVgAmMknpUlV7MHy1kkNJsmHnDibvSzHA2wp265bu2I"",""Notas!AR4:AR999"")"),"") | T2: =IFERROR(__xludf.DUMMYFUNCTION("IMPORTRANGE(""1JVgAmMknpUlV7MHy1kkNJsmHnDibvSzHA2wp265bu2I"",""Notas!AS4:AS999"")"),"x") -> x | U2: =IFERROR(__xludf.DUMMYFUNCTION("IMPORTRANGE(""1JVgAmMknpUlV7MHy1kkNJsmHnDibvSzHA2wp265bu2I"",""Notas!AT4:AT999"")"),"") | V2: =IFERROR(__xludf.DUMMYFUNCTION("IMPORTRANGE(""1JVgAmMknpUlV7MHy1kkNJsmHnDibvSzHA2wp265bu2I"",""Notas!AU4:AU999"")"),"") | W2: =IFERROR(__xludf.DUMMYFUNCTION("IMPORTRANGE(""1JVgAmMknpUlV7MHy1kkNJsmHnDibvSzHA2wp265bu2I"",""Notas!AV4:AV999"")"),"") | X2: =IFERROR(__xludf.DUMMYFUNCTION("IMPORTRANGE(""1JVgAmMknpUlV7MHy1kkNJsmHnDibvSzHA2wp265bu2I"",""Notas!AW4:AW999"")"),"") | Y2: =IFERROR(__xludf.DUMMYFUNCTION("IMPORTRANGE(""1JVgAmMknpUlV7MHy1kkNJsmHnDibvSzHA2wp265bu2I"",""Notas!AX4:AX999"")"),"") | Z2: x | AA2: x | AB2: =COUNTA(M2:Y2) -> 13 | AC2: =IF(M2="x",M$1000*1,"")*BY2 -> #VALUE! | AD2: =IF(N2="x",N$1000*1,"")*BZ2 -> #VALUE! | AE2: =IF(O2="x",O$1000*1,"")*CA2 -> 1 | AF2: =IF(P2="x",P$1000*1,"")*CB2 -> 1.2 | AG2: =IF(Q2="x",Q$1000*1,"")*CC2 -> #VALUE! | AH2: =IF(R2="x",R$1000*1,"")*CD2 -> #VALUE! | AI2: =IF(S2="x",S$1000*1,"")*CE2 -> #VALUE! | AJ2: =IF(T2="x",T$1000*1,"")*CF2 -> 1 | ... AQ2: =IF(AA2="x",AA$1000*1,"")*CM2 -> 0 | AR2: =SUM(AC2:AQ2) -> #VALUE! | AS2: =IFERROR(L2/AR2,"") | AT2: =IFERROR(__xludf.DUMMYFUNCTION("IMPORTRANGE(""1WAC1pNkHToaNboKeP-AiO20_ml3oOUXx6qp3zRuK__k"", ""NotaObras!DY4:DY999"")"),"") | AU2: =IFERROR(__xludf.DUMMYFUNCTION("IMPORTRANGE(""1WAC1pNkHToaNboKeP-AiO20_ml3oOUXx6qp3zRuK__k"", ""NotaObras!AS4:AS999"")"),10) -> 10 | AV2: =IFERROR(__xludf.DUMMYFUNCTION("IMPORTRANGE(""1WAC1pNkHToaNboKeP-AiO20_ml3oOUXx6qp3zRuK__k"", ""NotaObras!BG4:BG999"")"),10) -> 10 | AW2: =IFERROR(__xludf.DUMMYFUNCTION("IMPORTRANGE(""1WAC1pNkHToaNboKeP-AiO20_ml3oOUXx6qp3zRuK__k"", ""NotaObras!BU4:BU999"")"),10) -> 10 | AX2: =IFERROR(__xludf.DUMMYFUNCTION("IMPORTRANGE(""1WAC1pNkHToaNboKeP-AiO20_ml3oOUXx6qp3zRuK__k"", ""NotaObras!CI4:CI999"")"),10) -> 10 | AY2: =IFERROR(__xludf.DUMMYFUNCTION("IMPORTRANGE(""1WAC1pNkHToaNboKeP-AiO20_ml3oOUXx6qp3zRuK__k"", ""NotaObras!CW4:CW999"")"),"") | AZ2: =IFERROR(__xludf.DUMMYFUNCTION("IMPORTRANGE(""1WAC1pNkHToaNboKeP-AiO20_ml3oOUXx6qp3zRuK__k"", ""NotaObras!DK4:DK999"")"),"") | BA2: =IFERROR(__xludf.DUMMYFUNCTION("IMPORTRANGE(""1WAC1pNkHToaNboKeP-AiO20_ml3oOUXx6qp3zRuK__k"", ""NotaObras!AE4:AE999"")"),9.5) -> 9.5 | BB2: =IFERROR(__xludf.DUMMYFUNCTION("IMPORTRANGE(""1WAC1pNkHToaNboKeP-AiO20_ml3oOUXx6qp3zRuK__k"", ""NotaObras!FA4:FA999"")"),"") | BC2: =IFERROR(__xludf.DUMMYFUNCTION("IMPORTRANGE(""1WAC1pNkHToaNboKeP-AiO20_ml3oOUXx6qp3zRuK__k"", ""NotaObras!EM4:EM999"")"),"") | BD2: =IFERROR(__xludf.DUMMYFUNCTION("IMPORTRANGE(""1WAC1pNkHToaNboKeP-AiO20_ml3oOUXx6qp3zRuK__k"", ""NotaObras!FN4:FN999"")"),"") | BE2: =IFERROR(__xludf.DUMMYFUNCTION("IMPORTRANGE(""1WAC1pNkHToaNboKeP-AiO20_ml3oOUXx6qp3zRuK__k"", ""NotaObras!GA4:GA999"")"),"") | BF2: =IFERROR(__xludf.DUMMYFUNCTION("IMPORTRANGE(""1WAC1pNkHToaNboKeP-AiO20_ml3oOUXx6qp3zRuK__k"", ""NotaObras!GN4:GN999"")"),"") | BG2: =IFERROR(__xludf.DUMMYFUNCTION("IMPORTRANGE(""1WAC1pNkHToaNboKeP-AiO20_ml3oOUXx6qp3zRuK__k"", ""NotaObras!HB4:HB999"")"),10) -> 10 | BH2: =IFERROR(__xludf.DUMMYFUNCTION("IMPORTRANGE(""1WAC1pNkHToaNboKeP-AiO20_ml3oOUXx6qp3zRuK__k"", ""NotaObras!HQ4:HQ999"")"),10) -> 10 | BI2: =IF(AC2=0,"",AC2*$AS2*(AT2/10)) -> #VALUE! | BJ2: =IF(AD2=0,"",AD2*$AS2*(AU2/10)) -> #VALUE! | BK2: =IF(AE2=0,"",AE2*$AS2*(AV2/10)) -> #VALUE! | BL2: =IF(AF2=0,"",AF2*$AS2*(AW2/10)) -> #VALUE! | BM2: =IF(AG2=0,"",AG2*$AS2*(AX2/10)) -> #VALUE! | BN2: =IF(AH2=0,"",AH2*$AS2*(AY2/10)) -> #VALUE! | BO2: =IF(AI2=0,"",AI2*$AS2*(AZ2/10)) -> #VALUE! | BP2: =IF(AJ2=0,"",AJ2*$AS2*(BA2/10)) -> #VALUE! | ... BW2: =IF(AQ2=0,"",AQ2*$AS2*(BH2/10)) | BX2: =SUM(BI2:BW2) -> #VALUE! | BY2: =IF(M2="x","1","") | BZ2: =IF(N2="x","1","") | CA2: =IF(O2="x","1","") -> 1 | CB2: =IF(P2="x","1","") -> 1 | CC2: =IF(Q2="x","1","") | CD2: =IF(R2="x","1","") | CE2: =IF(S2="x","1","") | CF2: =IF(T2="x","1","") -> 1 | ... CH2: =IF(V2="x","1","")
A3: =IFERROR(__xludf.DUMMYFUNCTION("""COMPUTED_VALUE"""),"P775") -> P775 | B3: =IFERROR(__xludf.DUMMYFUNCTION("""COMPUTED_VALUE"""),"João Paulo Louback") -> João Paulo Louback | C3: x | D3: =IFERROR(__xludf.DUMMYFUNCTION("""COMPUTED_VALUE"""),45673) -> 45673 | E3: =IF(ISBLANK(D3),"",TEXT(D3,"MMMM")) -> janeiro | F3: =IFERROR(__xludf.DUMMYFUNCTION("""COMPUTED_VALUE"""),14) -> 14 | G3: =IFERROR(__xludf.DUMMYFUNCTION("""COMPUTED_VALUE"""),600) -> 600 | H3: =IF(ISBLANK(G3),"",F3*G3/1000) -> 8.4 | I3: =IF(ISBLANK(F3),"",IF(H3<5,200,IF(H3<10,300,IF(H3<20,500,IF(H3<30,750,IF(H3<50,1000,IF(H3<75,1500,IF(H3>75,2000)))))))) -> 300 | J3: =IFERROR(__xludf.DUMMYFUNCTION("""COMPUTED_VALUE"""),96.2222222222222) -> 96.222222 | K3: FALSE | L3: =IF(K3=TRUE(),0,IF(C3="x",IF(ISBLANK(A3),"", I3*(J3/100)),"PENDENTE")) -> 288.66667 | M3: =IFERROR(__xludf.DUMMYFUNCTION("""COMPUTED_VALUE"""),"x") -> x | Q3: =IFERROR(__xludf.DUMMYFUNCTION("""COMPUTED_VALUE"""),"x") -> x | R3: =IFERROR(__xludf.DUMMYFUNCTION("""COMPUTED_VALUE"""),"x") -> x | S3: =IFERROR(__xludf.DUMMYFUNCTION("""COMPUTED_VALUE"""),"x") -> x | Z3: x | AA3: x | AB3: =COUNTA(M3:Y3) -> 4 | AC3: =IF(M3="x",M$1000*1,"")*BY3 -> 1.2 | AD3: =IF(N3="x",N$1000*1,"")*BZ3 -> #VALUE! | AE3: =IF(O3="x",O$1000*1,"")*CA3 -> #VALUE! | AF3: =IF(P3="x",P$1000*1,"")*CB3 -> #VALUE! | AG3: =IF(Q3="x",Q$1000*1,"")*CC3 -> 1 | AH3: =IF(R3="x",R$1000*1,"")*CD3 -> 1 | AI3: =IF(S3="x",S$1000*1,"")*CE3 -> 1.1 | AJ3: =IF(T3="x",T$1000*1,"")*CF3 -> #VALUE! | ... AQ3: =IF(AA3="x",AA$1000*1,"")*CM3 -> 0 | AR3: =SUM(AC3:AQ3) -> #VALUE! | AS3: =IFERROR(L3/AR3,"") | AT3: =IFERROR(__xludf.DUMMYFUNCTION("""COMPUTED_VALUE"""),10) -> 10 | AU3: =IFERROR(__xludf.DUMMYFUNCTION("""COMPUTED_VALUE"""),"") | AV3: =IFERROR(__xludf.DUMMYFUNCTION("""COMPUTED_VALUE"""),"") | AW3: =IFERROR(__xludf.DUMMYFUNCTION("""COMPUTED_VALUE"""),"") | AX3: =IFERROR(__xludf.DUMMYFUNCTION("""COMPUTED_VALUE"""),10) -> 10 | AY3: =IFERROR(__xludf.DUMMYFUNCTION("""COMPUTED_VALUE"""),9.66666666666666) -> 9.6666667 | AZ3: =IFERROR(__xludf.DUMMYFUNCTION("""COMPUTED_VALUE"""),10) -> 10 | BA3: =IFERROR(__xludf.DUMMYFUNCTION("""COMPUTED_VALUE"""),"") | BB3: =IFERROR(__xludf.DUMMYFUNCTION("""COMPUTED_VALUE"""),"") | BC3: =IFERROR(__xludf.DUMMYFUNCTION("""COMPUTED_VALUE"""),"") | BD3: =IFERROR(__xludf.DUMMYFUNCTION("""COMPUTED_VALUE"""),"") | BF3: =IFERROR(__xludf.DUMMYFUNCTION("""COMPUTED_VALUE"""),"") | BG3: =IFERROR(__xludf.DUMMYFUNCTION("""COMPUTED_VALUE"""),10) -> 10 | BH3: =IFERROR(__xludf.DUMMYFUNCTION("""COMPUTED_VALUE"""),10) -> 10 | BI3: =IF(AC3=0,"",AC3*$AS3*(AT3/10)) -> #VALUE! | BJ3: =IF(AD3=0,"",AD3*$AS3*(AU3/10)) -> #VALUE! | BK3: =IF(AE3=0,"",AE3*$AS3*(AV3/10)) -> #VALUE! | BL3: =IF(AF3=0,"",AF3*$AS3*(AW3/10)) -> #VALUE! | BM3: =IF(AG3=0,"",AG3*$AS3*(AX3/10)) -> #VALUE! | BN3: =IF(AH3=0,"",AH3*$AS3*(AY3/10)) -> #VALUE! | BO3: =IF(AI3=0,"",AI3*$AS3*(AZ3/10)) -> #VALUE! | BP3: =IF(AJ3=0,"",AJ3*$AS3*(BA3/10)) -> #VALUE! | ... BW3: =IF(AQ3=0,"",AQ3*$AS3*(BH3/10)) | BX3: =SUM(BI3:BW3) -> #VALUE! | BY3: =IF(M3="x","1","") -> 1 | BZ3: =IF(N3="x","1","") | CA3: =IF(O3="x","1","") | CB3: =IF(P3="x","1","") | CC3: =IF(Q3="x","1","") -> 1 | CD3: =IF(R3="x","1","") -> 1 | CE3: =IF(S3="x","1","") -> 1 | CF3: =IF(T3="x","1","") | ... CH3: =IF(V3="x","1","")
A4: =IFERROR(__xludf.DUMMYFUNCTION("""COMPUTED_VALUE"""),"P767") -> P767 | B4: =IFERROR(__xludf.DUMMYFUNCTION("""COMPUTED_VALUE"""),"Joanice Ferreira") -> Joanice Ferreira | C4: x | D4: =IFERROR(__xludf.DUMMYFUNCTION("""COMPUTED_VALUE"""),45681) -> 45681 | E4: =IF(ISBLANK(D4),"",TEXT(D4,"MMMM")) -> janeiro | F4: =IFERROR(__xludf.DUMMYFUNCTION("""COMPUTED_VALUE"""),7) -> 7 | G4: =IFERROR(__xludf.DUMMYFUNCTION("""COMPUTED_VALUE"""),600) -> 600 | H4: =IF(ISBLANK(G4),"",F4*G4/1000) -> 4.2 | I4: =IF(ISBLANK(F4),"",IF(H4<5,200,IF(H4<10,300,IF(H4<20,500,IF(H4<30,750,IF(H4<50,1000,IF(H4<75,1500,IF(H4>75,2000)))))))) -> 200 | J4: =IFERROR(__xludf.DUMMYFUNCTION("""COMPUTED_VALUE"""),93.5555555555555) -> 93.555556 | K4: FALSE | L4: =IF(K4=TRUE(),0,IF(C4="x",IF(ISBLANK(A4),"", I4*(J4/100)),"PENDENTE")) -> 187.11111 | O4: =IFERROR(__xludf.DUMMYFUNCTION("""COMPUTED_VALUE"""),"x") -> x | P4: =IFERROR(__xludf.DUMMYFUNCTION("""COMPUTED_VALUE"""),"x") -> x | T4: =IFERROR(__xludf.DUMMYFUNCTION("""COMPUTED_VALUE"""),"x") -> x | Z4: x | AA4: x | AB4: =COUNTA(M4:Y4) -> 3 | AC4: =IF(M4="x",M$1000*1,"")*BY4 -> #VALUE! | AD4: =IF(N4="x",N$1000*1,"")*BZ4 -> #VALUE! | AE4: =IF(O4="x",O$1000*1,"")*CA4 -> 1 | AF4: =IF(P4="x",P$1000*1,"")*CB4 -> 1.2 | AG4: =IF(Q4="x",Q$1000*1,"")*CC4 -> #VALUE! | AH4: =IF(R4="x",R$1000*1,"")*CD4 -> #VALUE! | AI4: =IF(S4="x",S$1000*1,"")*CE4 -> #VALUE! | AJ4: =IF(T4="x",T$1000*1,"")*CF4 -> 1 | ... AQ4: =IF(AA4="x",AA$1000*1,"")*CM4 -> 0 | AR4: =SUM(AC4:AQ4) -> #VALUE! | AS4: =IFERROR(L4/AR4,"") | AT4: =IFERROR(__xludf.DUMMYFUNCTION("""COMPUTED_VALUE"""),"") | AU4: =IFERROR(__xludf.DUMMYFUNCTION("""COMPUTED_VALUE"""),10) -> 10 | AV4: =IFERROR(__xludf.DUMMYFUNCTION("""COMPUTED_VALUE"""),10) -> 10 | AW4: =IFERROR(__xludf.DUMMYFUNCTION("""COMPUTED_VALUE"""),10) -> 10 | AX4: =IFERROR(__xludf.DUMMYFUNCTION("""COMPUTED_VALUE"""),10) -> 10 | AY4: =IFERROR(__xludf.DUMMYFUNCTION("""COMPUTED_VALUE"""),"") | AZ4: =IFERROR(__xludf.DUMMYFUNCTION("""COMPUTED_VALUE"""),"") | BA4: =IFERROR(__xludf.DUMMYFUNCTION("""COMPUTED_VALUE"""),10) -> 10 | BB4: =IFERROR(__xludf.DUMMYFUNCTION("""COMPUTED_VALUE"""),"") | BC4: =IFERROR(__xludf.DUMMYFUNCTION("""COMPUTED_VALUE"""),"") | BD4: =IFERROR(__xludf.DUMMYFUNCTION("""COMPUTED_VALUE"""),"") | BF4: =IFERROR(__xludf.DUMMYFUNCTION("""COMPUTED_VALUE"""),"") | BG4: =IFERROR(__xludf.DUMMYFUNCTION("""COMPUTED_VALUE"""),10) -> 10 | BH4: =IFERROR(__xludf.DUMMYFUNCTION("""COMPUTED_VALUE"""),10) -> 10 | BI4: =IF(AC4=0,"",AC4*$AS4*(AT4/10)) -> #VALUE! | BJ4: =IF(AD4=0,"",AD4*$AS4*(AU4/10)) -> #VALUE! | BK4: =IF(AE4=0,"",AE4*$AS4*(AV4/10)) -> #VALUE! | BL4: =IF(AF4=0,"",AF4*$AS4*(AW4/10)) -> #VALUE! | BM4: =IF(AG4=0,"",AG4*$AS4*(AX4/10)) -> #VALUE! | BN4: =IF(AH4=0,"",AH4*$AS4*(AY4/10)) -> #VALUE! | BO4: =IF(AI4=0,"",AI4*$AS4*(AZ4/10)) -> #VALUE! | BP4: =IF(AJ4=0,"",AJ4*$AS4*(BA4/10)) -> #VALUE! | ... BW4: =IF(AQ4=0,"",AQ4*$AS4*(BH4/10)) | BX4: =SUM(BI4:BW4) -> #VALUE! | BY4: =IF(M4="x","1","") | BZ4: =IF(N4="x","1","") | CA4: =IF(O4="x","1","") -> 1 | CB4: =IF(P4="x","1","") -> 1 | CC4: =IF(Q4="x","1","") | CD4: =IF(R4="x","1","") | CE4: =IF(S4="x","1","") | CF4: =IF(T4="x","1","") -> 1 | ... CH4: =IF(V4="x","1","")
A5: =IFERROR(__xludf.DUMMYFUNCTION("""COMPUTED_VALUE"""),"P762") -> P762 | B5: =IFERROR(__xludf.DUMMYFUNCTION("""COMPUTED_VALUE"""),"Ana Carolina Freitas") -> Ana Carolina Freitas | C5: x | D5: =IFERROR(__xludf.DUMMYFUNCTION("""COMPUTED_VALUE"""),45679) -> 45679 | E5: =IF(ISBLANK(D5),"",TEXT(D5,"MMMM")) -> janeiro | F5: =IFERROR(__xludf.DUMMYFUNCTION("""COMPUTED_VALUE"""),24) -> 24 | G5: =IFERROR(__xludf.DUMMYFUNCTION("""COMPUTED_VALUE"""),585) -> 585 | H5: =IF(ISBLANK(G5),"",F5*G5/1000) -> 14.04 | I5: =IF(ISBLANK(F5),"",IF(H5<5,200,IF(H5<10,300,IF(H5<20,500,IF(H5<30,750,IF(H5<50,1000,IF(H5<75,1500,IF(H5>75,2000)))))))) -> 500 | J5: =IFERROR(__xludf.DUMMYFUNCTION("""COMPUTED_VALUE"""),96.3888888888888) -> 96.388889 | K5: FALSE | L5: =IF(K5=TRUE(),0,IF(C5="x",IF(ISBLANK(A5),"", I5*(J5/100)),"PENDENTE")) -> 481.94444 | O5: =IFERROR(__xludf.DUMMYFUNCTION("""COMPUTED_VALUE"""),"x") -> x | P5: =IFERROR(__xludf.DUMMYFUNCTION("""COMPUTED_VALUE"""),"x") -> x | T5: =IFERROR(__xludf.DUMMYFUNCTION("""COMPUTED_VALUE"""),"x") -> x | Z5: x | AA5: x | AB5: =COUNTA(M5:Y5) -> 3 | AC5: =IF(M5="x",M$1000*1,"")*BY5 -> #VALUE! | AD5: =IF(N5="x",N$1000*1,"")*BZ5 -> #VALUE! | AE5: =IF(O5="x",O$1000*1,"")*CA5 -> 1 | AF5: =IF(P5="x",P$1000*1,"")*CB5 -> 1.2 | AG5: =IF(Q5="x",Q$1000*1,"")*CC5 -> #VALUE! | AH5: =IF(R5="x",R$1000*1,"")*CD5 -> #VALUE! | AI5: =IF(S5="x",S$1000*1,"")*CE5 -> #VALUE! | AJ5: =IF(T5="x",T$1000*1,"")*CF5 -> 1 | ... AQ5: =IF(AA5="x",AA$1000*1,"")*CM5 -> 0 | AR5: =SUM(AC5:AQ5) -> #VALUE! | AS5: =IFERROR(L5/AR5,"") | AT5: =IFERROR(__xludf.DUMMYFUNCTION("""COMPUTED_VALUE"""),"") | AU5: =IFERROR(__xludf.DUMMYFUNCTION("""COMPUTED_VALUE"""),10) -> 10 | AV5: =IFERROR(__xludf.DUMMYFUNCTION("""COMPUTED_VALUE"""),10) -> 10 | AW5: =IFERROR(__xludf.DUMMYFUNCTION("""COMPUTED_VALUE"""),10) -> 10 | AX5: =IFERROR(__xludf.DUMMYFUNCTION("""COMPUTED_VALUE"""),10) -> 10 | AY5: =IFERROR(__xludf.DUMMYFUNCTION("""COMPUTED_VALUE"""),"") | AZ5: =IFERROR(__xludf.DUMMYFUNCTION("""COMPUTED_VALUE"""),"") | BA5: =IFERROR(__xludf.DUMMYFUNCTION("""COMPUTED_VALUE"""),7) -> 7 | BB5: =IFERROR(__xludf.DUMMYFUNCTION("""COMPUTED_VALUE"""),"") | BC5: =IFERROR(__xludf.DUMMYFUNCTION("""COMPUTED_VALUE"""),"") | BD5: =IFERROR(__xludf.DUMMYFUNCTION("""COMPUTED_VALUE"""),"") | BF5: =IFERROR(__xludf.DUMMYFUNCTION("""COMPUTED_VALUE"""),"") | BG5: =IFERROR(__xludf.DUMMYFUNCTION("""COMPUTED_VALUE"""),9.66666666666666) -> 9.6666667 | BH5: =IFERROR(__xludf.DUMMYFUNCTION("""COMPUTED_VALUE"""),9.33333333333333) -> 9.3333333 | BI5: =IF(AC5=0,"",AC5*$AS5*(AT5/10)) -> #VALUE! | BJ5: =IF(AD5=0,"",AD5*$AS5*(AU5/10)) -> #VALUE! | BK5: =IF(AE5=0,"",AE5*$AS5*(AV5/10)) -> #VALUE! | BL5: =IF(AF5=0,"",AF5*$AS5*(AW5/10)) -> #VALUE! | BM5: =IF(AG5=0,"",AG5*$AS5*(AX5/10)) -> #VALUE! | BN5: =IF(AH5=0,"",AH5*$AS5*(AY5/10)) -> #VALUE! | BO5: =IF(AI5=0,"",AI5*$AS5*(AZ5/10)) -> #VALUE! | BP5: =IF(AJ5=0,"",AJ5*$AS5*(BA5/10)) -> #VALUE! | ... BW5: =IF(AQ5=0,"",AQ5*$AS5*(BH5/10)) | BX5: =SUM(BI5:BW5) -> #VALUE! | BY5: =IF(M5="x","1","") | BZ5: =IF(N5="x","1","") | CA5: =IF(O5="x","1","") -> 1 | CB5: =IF(P5="x","1","") -> 1 | CC5: =IF(Q5="x","1","") | CD5: =IF(R5="x","1","") | CE5: =IF(S5="x","1","") | CF5: =IF(T5="x","1","") -> 1 | ... CH5: =IF(V5="x","1","")
A6: =IFERROR(__xludf.DUMMYFUNCTION("""COMPUTED_VALUE"""),"P754") -> P754 | B6: =IFERROR(__xludf.DUMMYFUNCTION("""COMPUTED_VALUE"""),"Lúcia Aparecida Moura") -> Lúcia Aparecida Moura | C6: x | D6: =IFERROR(__xludf.DUMMYFUNCTION("""COMPUTED_VALUE"""),45675) -> 45675 | E6: =IF(ISBLANK(D6),"",TEXT(D6,"MMMM")) -> janeiro | F6: =IFERROR(__xludf.DUMMYFUNCTION("""COMPUTED_VALUE"""),28) -> 28 | G6: =IFERROR(__xludf.DUMMYFUNCTION("""COMPUTED_VALUE"""),585) -> 585 | H6: =IF(ISBLANK(G6),"",F6*G6/1000) -> 16.38 | I6: =IF(ISBLANK(F6),"",IF(H6<5,200,IF(H6<10,300,IF(H6<20,500,IF(H6<30,750,IF(H6<50,1000,IF(H6<75,1500,IF(H6>75,2000)))))))) -> 500 | J6: =IFERROR(__xludf.DUMMYFUNCTION("""COMPUTED_VALUE"""),73.4444444444444) -> 73.444444 | K6: FALSE | L6: =IF(K6=TRUE(),0,IF(C6="x",IF(ISBLANK(A6),"", I6*(J6/100)),"PENDENTE")) -> 367.22222 | O6: =IFERROR(__xludf.DUMMYFUNCTION("""COMPUTED_VALUE"""),"x") -> x | P6: =IFERROR(__xludf.DUMMYFUNCTION("""COMPUTED_VALUE"""),"x") -> x | T6: =IFERROR(__xludf.DUMMYFUNCTION("""COMPUTED_VALUE"""),"x") -> x | Z6: x | AA6: x | AB6: =COUNTA(M6:Y6) -> 3 | AC6: =IF(M6="x",M$1000*1,"")*BY6 -> #VALUE! | AD6: =IF(N6="x",N$1000*1,"")*BZ6 -> #VALUE! | AE6: =IF(O6="x",O$1000*1,"")*CA6 -> 1 | AF6: =IF(P6="x",P$1000*1,"")*CB6 -> 1.2 | AG6: =IF(Q6="x",Q$1000*1,"")*CC6 -> #VALUE! | AH6: =IF(R6="x",R$1000*1,"")*CD6 -> #VALUE! | AI6: =IF(S6="x",S$1000*1,"")*CE6 -> #VALUE! | AJ6: =IF(T6="x",T$1000*1,"")*CF6 -> 1 | ... AQ6: =IF(AA6="x",AA$1000*1,"")*CM6 -> 0 | AR6: =SUM(AC6:AQ6) -> #VALUE! | AS6: =IFERROR(L6/AR6,"") | AT6: =IFERROR(__xludf.DUMMYFUNCTION("""COMPUTED_VALUE"""),"") | AU6: =IFERROR(__xludf.DUMMYFUNCTION("""COMPUTED_VALUE"""),10) -> 10 | AV6: =IFERROR(__xludf.DUMMYFUNCTION("""COMPUTED_VALUE"""),10) -> 10 | AW6: =IFERROR(__xludf.DUMMYFUNCTION("""COMPUTED_VALUE"""),10) -> 10 | AX6: =IFERROR(__xludf.DUMMYFUNCTION("""COMPUTED_VALUE"""),10) -> 10 | AY6: =IFERROR(__xludf.DUMMYFUNCTION("""COMPUTED_VALUE"""),"") | AZ6: =IFERROR(__xludf.DUMMYFUNCTION("""COMPUTED_VALUE"""),"") | BA6: =IFERROR(__xludf.DUMMYFUNCTION("""COMPUTED_VALUE"""),10) -> 10 | BB6: =IFERROR(__xludf.DUMMYFUNCTION("""COMPUTED_VALUE"""),"") | BC6: =IFERROR(__xludf.DUMMYFUNCTION("""COMPUTED_VALUE"""),"") | BD6: =IFERROR(__xludf.DUMMYFUNCTION("""COMPUTED_VALUE"""),"") | BF6: =IFERROR(__xludf.DUMMYFUNCTION("""COMPUTED_VALUE"""),"") | BG6: =IFERROR(__xludf.DUMMYFUNCTION("""COMPUTED_VALUE"""),10) -> 10 | BH6: =IFERROR(__xludf.DUMMYFUNCTION("""COMPUTED_VALUE"""),10) -> 10 | BI6: =IF(AC6=0,"",AC6*$AS6*(AT6/10)) -> #VALUE! | BJ6: =IF(AD6=0,"",AD6*$AS6*(AU6/10)) -> #VALUE! | BK6: =IF(AE6=0,"",AE6*$AS6*(AV6/10)) -> #VALUE! | BL6: =IF(AF6=0,"",AF6*$AS6*(AW6/10)) -> #VALUE! | BM6: =IF(AG6=0,"",AG6*$AS6*(AX6/10)) -> #VALUE! | BN6: =IF(AH6=0,"",AH6*$AS6*(AY6/10)) -> #VALUE! | BO6: =IF(AI6=0,"",AI6*$AS6*(AZ6/10)) -> #VALUE! | BP6: =IF(AJ6=0,"",AJ6*$AS6*(BA6/10)) -> #VALUE! | ... BW6: =IF(AQ6=0,"",AQ6*$AS6*(BH6/10)) | BX6: =SUM(BI6:BW6) -> #VALUE! | BY6: =IF(M6="x","1","") | BZ6: =IF(N6="x","1","") | CA6: =IF(O6="x","1","") -> 1 | CB6: =IF(P6="x","1","") -> 1 | CC6: =IF(Q6="x","1","") | CD6: =IF(R6="x","1","") | CE6: =IF(S6="x","1","") | CF6: =IF(T6="x","1","") -> 1 | ... CH6: =IF(V6="x","1","")
A7: =IFERROR(__xludf.DUMMYFUNCTION("""COMPUTED_VALUE"""),"?") -> ? | B7: =IFERROR(__xludf.DUMMYFUNCTION("""COMPUTED_VALUE"""),"?") -> ? | C7: x | E7: =IF(ISBLANK(D7),"",TEXT(D7,"MMMM")) | I7: 500 | J7: =IFERROR(__xludf.DUMMYFUNCTION("""COMPUTED_VALUE"""),83.1481481481481) -> 83.148148 | K7: FALSE | L7: =IF(K7=TRUE(),0,IF(C7="x",IF(ISBLANK(A7),"", I7*(J7/100)),"PENDENTE")) -> 415.74074 | M7: =IFERROR(__xludf.DUMMYFUNCTION("""COMPUTED_VALUE"""),"x") -> x | Q7: =IFERROR(__xludf.DUMMYFUNCTION("""COMPUTED_VALUE"""),"x") -> x | R7: =IFERROR(__xludf.DUMMYFUNCTION("""COMPUTED_VALUE"""),"x") -> x | S7: =IFERROR(__xludf.DUMMYFUNCTION("""COMPUTED_VALUE"""),"x") -> x | Z7: x | AA7: x | AB7: =COUNTA(M7:Y7) -> 4 | AC7: =IF(M7="x",M$1000*1,"")*BY7 -> 1.2 | AD7: =IF(N7="x",N$1000*1,"")*BZ7 -> #VALUE! | AE7: =IF(O7="x",O$1000*1,"")*CA7 -> #VALUE! | AF7: =IF(P7="x",P$1000*1,"")*CB7 -> #VALUE! | AG7: =IF(Q7="x",Q$1000*1,"")*CC7 -> 1 | AH7: =IF(R7="x",R$1000*1,"")*CD7 -> 1 | AI7: =IF(S7="x",S$1000*1,"")*CE7 -> 1.1 | AJ7: =IF(T7="x",T$1000*1,"")*CF7 -> #VALUE! | ... AQ7: =IF(AA7="x",AA$1000*1,"")*CM7 -> 0 | AR7: =SUM(AC7:AQ7) -> #VALUE! | AS7: =IFERROR(L7/AR7,"") | AT7: =IFERROR(__xludf.DUMMYFUNCTION("""COMPUTED_VALUE"""),10) -> 10 | AU7: =IFERROR(__xludf.DUMMYFUNCTION("""COMPUTED_VALUE"""),"") | AV7: =IFERROR(__xludf.DUMMYFUNCTION("""COMPUTED_VALUE"""),"") | AW7: =IFERROR(__xludf.DUMMYFUNCTION("""COMPUTED_VALUE"""),"") | AX7: =IFERROR(__xludf.DUMMYFUNCTION("""COMPUTED_VALUE"""),10) -> 10 | AY7: =IFERROR(__xludf.DUMMYFUNCTION("""COMPUTED_VALUE"""),9.33333333333333) -> 9.3333333 | AZ7: =IFERROR(__xludf.DUMMYFUNCTION("""COMPUTED_VALUE"""),10) -> 10 | BA7: =IFERROR(__xludf.DUMMYFUNCTION("""COMPUTED_VALUE"""),"") | BB7: =IFERROR(__xludf.DUMMYFUNCTION("""COMPUTED_VALUE"""),"") | BC7: =IFERROR(__xludf.DUMMYFUNCTION("""COMPUTED_VALUE"""),"") | BD7: =IFERROR(__xludf.DUMMYFUNCTION("""COMPUTED_VALUE"""),"") | BF7: =IFERROR(__xludf.DUMMYFUNCTION("""COMPUTED_VALUE"""),"") | BG7: =IFERROR(__xludf.DUMMYFUNCTION("""COMPUTED_VALUE"""),10) -> 10 | BH7: =IFERROR(__xludf.DUMMYFUNCTION("""COMPUTED_VALUE"""),10) -> 10 | BQ7: =IF(AK7=0,"",AK7*$AS7*(BB7/10)) -> #VALUE! | BR7: =IF(AL7=0,"",AL7*$AS7*(BC7/10)) -> #VALUE! | BS7: =IF(AM7=0,"",AM7*$AS7*(BD7/10)) -> #VALUE! | BT7: =IF(AN7=0,"",AN7*$AS7*(BE7/10)) -> #VALUE! | BU7: =IF(AO7=0,"",AO7*$AS7*(BF7/10)) -> #VALUE! | BV7: =IF(AP7=0,"",AP7*$AS7*(BG7/10)) | BW7: =IF(AQ7=0,"",AQ7*$AS7*(BH7/10)) | BX7: =SUM(BI7:BW7) -> #VALUE! | BY7: =IF(M7="x","1","") -> 1 | BZ7: =IF(N7="x","1","") | CA7: =IF(O7="x","1","") | CB7: =IF(P7="x","1","") | CC7: =IF(Q7="x","1","") -> 1 | CD7: =IF(R7="x","1","") -> 1 | CE7: =IF(S7="x","1","") -> 1 | CF7: =IF(T7="x","1","") | ... CH7: =IF(V7="x","1","")
A8: =IFERROR(__xludf.DUMMYFUNCTION("""COMPUTED_VALUE"""),"P724") -> P724 | B8: =IFERROR(__xludf.DUMMYFUNCTION("""COMPUTED_VALUE"""),"Rodrigo (SABOR AMIL) Mercearia") -> Rodrigo (SABOR AMIL) Mercearia | C8: x | D8: =IFERROR(__xludf.DUMMYFUNCTION("""COMPUTED_VALUE"""),45688) -> 45688 | E8: =IF(ISBLANK(D8),"",TEXT(D8,"MMMM")) -> janeiro | F8: =IFERROR(__xludf.DUMMYFUNCTION("""COMPUTED_VALUE"""),21) -> 21 | G8: =IFERROR(__xludf.DUMMYFUNCTION("""COMPUTED_VALUE"""),550) -> 550 | H8: =IF(ISBLANK(G8),"",F8*G8/1000) -> 11.55 | I8: =IF(ISBLANK(F8),"",IF(H8<5,200,IF(H8<10,300,IF(H8<20,500,IF(H8<30,750,IF(H8<50,1000,IF(H8<75,1500,IF(H8>75,2000)))))))) -> 500 | J8: =IFERROR(__xludf.DUMMYFUNCTION("""COMPUTED_VALUE"""),99.753086419753) -> 99.753086 | K8: FALSE | L8: =IF(K8=TRUE(),0,IF(C8="x",IF(ISBLANK(A8),"", I8*(J8/100)),"PENDENTE")) -> 498.76543 | M8: =IFERROR(__xludf.DUMMYFUNCTION("""COMPUTED_VALUE"""),"x") -> x | Q8: =IFERROR(__xludf.DUMMYFUNCTION("""COMPUTED_VALUE"""),"x") -> x | R8: =IFERROR(__xludf.DUMMYFUNCTION("""COMPUTED_VALUE"""),"x") -> x | S8: =IFERROR(__xludf.DUMMYFUNCTION("""COMPUTED_VALUE"""),"x") -> x | Z8: x | AA8: x | AB8: =COUNTA(M8:Y8) -> 4 | AC8: =IF(M8="x",M$1000*1,"")*BY8 -> 1.2 | AD8: =IF(N8="x",N$1000*1,"")*BZ8 -> #VALUE! | AE8: =IF(O8="x",O$1000*1,"")*CA8 -> #VALUE! | AF8: =IF(P8="x",P$1000*1,"")*CB8 -> #VALUE! | AG8: =IF(Q8="x",Q$1000*1,"")*CC8 -> 1 | AH8: =IF(R8="x",R$1000*1,"")*CD8 -> 1 | AI8: =IF(S8="x",S$1000*1,"")*CE8 -> 1.1 | AJ8: =IF(T8="x",T$1000*1,"")*CF8 -> #VALUE! | ... AQ8: =IF(AA8="x",AA$1000*1,"")*CM8 -> 0 | AR8: =SUM(AC8:AQ8) -> #VALUE! | AS8: =IFERROR(L8/AR8,"") | AT8: =IFERROR(__xludf.DUMMYFUNCTION("""COMPUTED_VALUE"""),10) -> 10 | AU8: =IFERROR(__xludf.DUMMYFUNCTION("""COMPUTED_VALUE"""),"") | AV8: =IFERROR(__xludf.DUMMYFUNCTION("""COMPUTED_VALUE"""),"") | AW8: =IFERROR(__xludf.DUMMYFUNCTION("""COMPUTED_VALUE"""),"") | AX8: =IFERROR(__xludf.DUMMYFUNCTION("""COMPUTED_VALUE"""),10) -> 10 | AY8: =IFERROR(__xludf.DUMMYFUNCTION("""COMPUTED_VALUE"""),9.66666666666666) -> 9.6666667 | AZ8: =IFERROR(__xludf.DUMMYFUNCTION("""COMPUTED_VALUE"""),10) -> 10 | BA8: =IFERROR(__xludf.DUMMYFUNCTION("""COMPUTED_VALUE"""),"") | BB8: =IFERROR(__xludf.DUMMYFUNCTION("""COMPUTED_VALUE"""),"") | BC8: =IFERROR(__xludf.DUMMYFUNCTION("""COMPUTED_VALUE"""),"") | BD8: =IFERROR(__xludf.DUMMYFUNCTION("""COMPUTED_VALUE"""),"") | BF8: =IFERROR(__xludf.DUMMYFUNCTION("""COMPUTED_VALUE"""),"") | BG8: =IFERROR(__xludf.DUMMYFUNCTION("""COMPUTED_VALUE"""),10) -> 10 | BH8: =IFERROR(__xludf.DUMMYFUNCTION("""COMPUTED_VALUE"""),10) -> 10 | BI8: =IF(AC8=0,"",AC8*$AS8*(AT8/10)) -> #VALUE! | BJ8: =IF(AD8=0,"",AD8*$AS8*(AU8/10)) -> #VALUE! | BK8: =IF(AE8=0,"",AE8*$AS8*(AV8/10)) -> #VALUE! | BL8: =IF(AF8=0,"",AF8*$AS8*(AW8/10)) -> #VALUE! | BM8: =IF(AG8=0,"",AG8*$AS8*(AX8/10)) -> #VALUE! | BN8: =IF(AH8=0,"",AH8*$AS8*(AY8/10)) -> #VALUE! | BO8: =IF(AI8=0,"",AI8*$AS8*(AZ8/10)) -> #VALUE! | BP8: =IF(AJ8=0,"",AJ8*$AS8*(BA8/10)) -> #VALUE! | ... BW8: =IF(AQ8=0,"",AQ8*$AS8*(BH8/10)) | BX8: =SUM(BI8:BW8) -> #VALUE! | BY8: =IF(M8="x","1","") -> 1 | BZ8: =IF(N8="x","1","") | CA8: =IF(O8="x","1","") | CB8: =IF(P8="x","1","") | CC8: =IF(Q8="x","1","") -> 1 | CD8: =IF(R8="x","1","") -> 1 | CE8: =IF(S8="x","1","") -> 1 | CF8: =IF(T8="x","1","") | ... CH8: =IF(V8="x","1","")
A9: =IFERROR(__xludf.DUMMYFUNCTION("""COMPUTED_VALUE"""),"P782") -> P782 | B9: =IFERROR(__xludf.DUMMYFUNCTION("""COMPUTED_VALUE"""),"Mariolucio Dutra Brandão") -> Mariolucio Dutra Brandão | C9: x | D9: =IFERROR(__xludf.DUMMYFUNCTION("""COMPUTED_VALUE"""),45686) -> 45686 | E9: =IF(ISBLANK(D9),"",TEXT(D9,"MMMM")) -> janeiro | F9: =IFERROR(__xludf.DUMMYFUNCTION("""COMPUTED_VALUE"""),11) -> 11 | G9: =IFERROR(__xludf.DUMMYFUNCTION("""COMPUTED_VALUE"""),600) -> 600 | H9: =IF(ISBLANK(G9),"",F9*G9/1000) -> 6.6 | I9: =IF(ISBLANK(F9),"",IF(H9<5,200,IF(H9<10,300,IF(H9<20,500,IF(H9<30,750,IF(H9<50,1000,IF(H9<75,1500,IF(H9>75,2000)))))))) -> 300 | J9: =IFERROR(__xludf.DUMMYFUNCTION("""COMPUTED_VALUE"""),93.6666666666666) -> 93.666667 | K9: FALSE | L9: =IF(K9=TRUE(),0,IF(C9="x",IF(ISBLANK(A9),"", I9*(J9/100)),"PENDENTE")) -> 281 | O9: =IFERROR(__xludf.DUMMYFUNCTION("""COMPUTED_VALUE"""),"x") -> x | Q9: =IFERROR(__xludf.DUMMYFUNCTION("""COMPUTED_VALUE"""),"x") -> x | R9: =IFERROR(__xludf.DUMMYFUNCTION("""COMPUTED_VALUE"""),"x") -> x | S9: =IFERROR(__xludf.DUMMYFUNCTION("""COMPUTED_VALUE"""),"x") -> x | Z9: x | AA9: x | AB9: =COUNTA(M9:Y9) -> 4 | AC9: =IF(M9="x",M$1000*1,"")*BY9 -> #VALUE! | AD9: =IF(N9="x",N$1000*1,"")*BZ9 -> #VALUE! | AE9: =IF(O9="x",O$1000*1,"")*CA9 -> 1 | AF9: =IF(P9="x",P$1000*1,"")*CB9 -> #VALUE! | AG9: =IF(Q9="x",Q$1000*1,"")*CC9 -> 1 | AH9: =IF(R9="x",R$1000*1,"")*CD9 -> 1 | AI9: =IF(S9="x",S$1000*1,"")*CE9 -> 1.1 | AJ9: =IF(T9="x",T$1000*1,"")*CF9 -> #VALUE! | ... AQ9: =IF(AA9="x",AA$1000*1,"")*CM9 -> 0 | AR9: =SUM(AC9:AQ9) -> #VALUE! | AS9: =IFERROR(L9/AR9,"") | AT9: =IFERROR(__xludf.DUMMYFUNCTION("""COMPUTED_VALUE"""),"") | AU9: =IFERROR(__xludf.DUMMYFUNCTION("""COMPUTED_VALUE"""),"") | AV9: =IFERROR(__xludf.DUMMYFUNCTION("""COMPUTED_VALUE"""),10) -> 10 | AW9: =IFERROR(__xludf.DUMMYFUNCTION("""COMPUTED_VALUE"""),"") | AX9: =IFERROR(__xludf.DUMMYFUNCTION("""COMPUTED_VALUE"""),10) -> 10 | AY9: =IFERROR(__xludf.DUMMYFUNCTION("""COMPUTED_VALUE"""),10) -> 10 | AZ9: =IFERROR(__xludf.DUMMYFUNCTION("""COMPUTED_VALUE"""),10) -> 10 | BA9: =IFERROR(__xludf.DUMMYFUNCTION("""COMPUTED_VALUE"""),10) -> 10 | BB9: =IFERROR(__xludf.DUMMYFUNCTION("""COMPUTED_VALUE"""),"") | BC9: =IFERROR(__xludf.DUMMYFUNCTION("""COMPUTED_VALUE"""),"") | BD9: =IFERROR(__xludf.DUMMYFUNCTION("""COMPUTED_VALUE"""),"") | BF9: =IFERROR(__xludf.DUMMYFUNCTION("""COMPUTED_VALUE"""),"") | BG9: =IFERROR(__xludf.DUMMYFUNCTION("""COMPUTED_VALUE"""),10) -> 10 | BH9: =IFERROR(__xludf.DUMMYFUNCTION("""COMPUTED_VALUE"""),10) -> 10 | BI9: =IF(AC9=0,"",AC9*$AS9*(AT9/10)) -> #VALUE! | BJ9: =IF(AD9=0,"",AD9*$AS9*(AU9/10)) -> #VALUE! | BK9: =IF(AE9=0,"",AE9*$AS9*(AV9/10)) -> #VALUE! | BL9: =IF(AF9=0,"",AF9*$AS9*(AW9/10)) -> #VALUE! | BM9: =IF(AG9=0,"",AG9*$AS9*(AX9/10)) -> #VALUE! | BN9: =IF(AH9=0,"",AH9*$AS9*(AY9/10)) -> #VALUE! | BO9: =IF(AI9=0,"",AI9*$AS9*(AZ9/10)) -> #VALUE! | BP9: =IF(AJ9=0,"",AJ9*$AS9*(BA9/10)) -> #VALUE! | ... BW9: =IF(AQ9=0,"",AQ9*$AS9*(BH9/10)) | BX9: =SUM(BI9:BW9) -> #VALUE! | BY9: =IF(M9="x","1","") | BZ9: =IF(N9="x","1","") | CA9: =IF(O9="x","1","") -> 1 | CB9: =IF(P9="x","1","") | CC9: =IF(Q9="x","1","") -> 1 | CD9: =IF(R9="x","1","") -> 1 | CE9: =IF(S9="x","1","") -> 1 | CF9: =IF(T9="x","1","") | ... CH9: =IF(V9="x","1","")
A10: =IFERROR(__xludf.DUMMYFUNCTION("""COMPUTED_VALUE"""),"P729") -> P729 | B10: =IFERROR(__xludf.DUMMYFUNCTION("""COMPUTED_VALUE"""),"Antônio Claudio da Costa") -> Antônio Claudio da Costa | C10: x | D10: =IFERROR(__xludf.DUMMYFUNCTION("""COMPUTED_VALUE"""),45685) -> 45685 | E10: =IF(ISBLANK(D10),"",TEXT(D10,"MMMM")) -> janeiro | F10: =IFERROR(__xludf.DUMMYFUNCTION("""COMPUTED_VALUE"""),18) -> 18 | G10: =IFERROR(__xludf.DUMMYFUNCTION("""COMPUTED_VALUE"""),550) -> 550 | H10: =IF(ISBLANK(G10),"",F10*G10/1000) -> 9.9 | I10: =IF(ISBLANK(F10),"",IF(H10<5,200,IF(H10<10,300,IF(H10<20,500,IF(H10<30,750,IF(H10<50,1000,IF(H10<75,1500,IF(H10>75,2000)))))))) -> 300 | J10: =IFERROR(__xludf.DUMMYFUNCTION("""COMPUTED_VALUE"""),88.8333333333333) -> 88.833333 | K10: FALSE | L10: =IF(K10=TRUE(),0,IF(C10="x",IF(ISBLANK(A10),"", I10*(J10/100)),"PENDENTE")) -> 266.5 | M10: =IFERROR(__xludf.DUMMYFUNCTION("""COMPUTED_VALUE"""),"x") -> x | Q10: =IFERROR(__xludf.DUMMYFUNCTION("""COMPUTED_VALUE"""),"x") -> x | R10: =IFERROR(__xludf.DUMMYFUNCTION("""COMPUTED_VALUE"""),"x") -> x | Z10: x | AA10: x | AB10: =COUNTA(M10:Y10) -> 3 | AC10: =IF(M10="x",M$1000*1,"")*BY10 -> 1.2 | AD10: =IF(N10="x",N$1000*1,"")*BZ10 -> #VALUE! | AE10: =IF(O10="x",O$1000*1,"")*CA10 -> #VALUE! | AF10: =IF(P10="x",P$1000*1,"")*CB10 -> #VALUE! | AG10: =IF(Q10="x",Q$1000*1,"")*CC10 -> 1 | AH10: =IF(R10="x",R$1000*1,"")*CD10 -> 1 | AI10: =IF(S10="x",S$1000*1,"")*CE10 -> #VALUE! | AJ10: =IF(T10="x",T$1000*1,"")*CF10 -> #VALUE! | ... AQ10: =IF(AA10="x",AA$1000*1,"")*CM10 -> 0 | AR10: =SUM(AC10:AQ10) -> #VALUE! | AS10: =IFERROR(L10/AR10,"") | AT10: =IFERROR(__xludf.DUMMYFUNCTION("""COMPUTED_VALUE"""),10) -> 10 | AU10: =IFERROR(__xludf.DUMMYFUNCTION("""COMPUTED_VALUE"""),"") | AV10: =IFERROR(__xludf.DUMMYFUNCTION("""COMPUTED_VALUE"""),"") | AW10: =IFERROR(__xludf.DUMMYFUNCTION("""COMPUTED_VALUE"""),"") | AX10: =IFERROR(__xludf.DUMMYFUNCTION("""COMPUTED_VALUE"""),10) -> 10 | AY10: =IFERROR(__xludf.DUMMYFUNCTION("""COMPUTED_VALUE"""),10) -> 10 | AZ10: =IFERROR(__xludf.DUMMYFUNCTION("""COMPUTED_VALUE"""),"") | BA10: =IFERROR(__xludf.DUMMYFUNCTION("""COMPUTED_VALUE"""),"") | BB10: =IFERROR(__xludf.DUMMYFUNCTION("""COMPUTED_VALUE"""),"") | BC10: =IFERROR(__xludf.DUMMYFUNCTION("""COMPUTED_VALUE"""),"") | BD10: =IFERROR(__xludf.DUMMYFUNCTION("""COMPUTED_VALUE"""),"") | BF10: =IFERROR(__xludf.DUMMYFUNCTION("""COMPUTED_VALUE"""),"") | BG10: =IFERROR(__xludf.DUMMYFUNCTION("""COMPUTED_VALUE"""),10) -> 10 | BH10: =IFERROR(__xludf.DUMMYFUNCTION("""COMPUTED_VALUE"""),10) -> 10 | BI10: =IF(AC10=0,"",AC10*$AS10*(AT10/10)) -> #VALUE! | BJ10: =IF(AD10=0,"",AD10*$AS10*(AU10/10)) -> #VALUE! | BK10: =IF(AE10=0,"",AE10*$AS10*(AV10/10)) -> #VALUE! | BL10: =IF(AF10=0,"",AF10*$AS10*(AW10/10)) -> #VALUE! | BM10: =IF(AG10=0,"",AG10*$AS10*(AX10/10)) -> #VALUE! | BN10: =IF(AH10=0,"",AH10*$AS10*(AY10/10)) -> #VALUE! | BO10: =IF(AI10=0,"",AI10*$AS10*(AZ10/10)) -> #VALUE! | BP10: =IF(AJ10=0,"",AJ10*$AS10*(BA10/10)) -> #VALUE! | ... BW10: =IF(AQ10=0,"",AQ10*$AS10*(BH10/10)) | BX10: =SUM(BI10:BW10) -> #VALUE! | BY10: =IF(M10="x","1","") -> 1 | BZ10: =IF(N10="x","1","") | CA10: =IF(O10="x","1","") | CB10: =IF(P10="x","1","") | CC10: =IF(Q10="x","1","") -> 1 | CD10: =IF(R10="x","1","") -> 1 | CE10: =IF(S10="x","1","") | CF10: =IF(T10="x","1","") | ... CH10: =IF(V10="x","1","")
A11: =IFERROR(__xludf.DUMMYFUNCTION("""COMPUTED_VALUE"""),"P781") -> P781 | B11: =IFERROR(__xludf.DUMMYFUNCTION("""COMPUTED_VALUE"""),"Leonilson Barbosa Lima ") -> Leonilson Barbosa Lima | C11: x | D11: =IFERROR(__xludf.DUMMYFUNCTION("""COMPUTED_VALUE"""),45684) -> 45684 | E11: =IF(ISBLANK(D11),"",TEXT(D11,"MMMM")) -> janeiro | F11: =IFERROR(__xludf.DUMMYFUNCTION("""COMPUTED_VALUE"""),5) -> 5 | G11: =IFERROR(__xludf.DUMMYFUNCTION("""COMPUTED_VALUE"""),600) -> 600 | H11: =IF(ISBLANK(G11),"",F11*G11/1000) -> 3 | I11: =IF(ISBLANK(F11),"",IF(H11<5,200,IF(H11<10,300,IF(H11<20,500,IF(H11<30,750,IF(H11<50,1000,IF(H11<75,1500,IF(H11>75,2000)))))))) -> 200 | J11: =IFERROR(__xludf.DUMMYFUNCTION("""COMPUTED_VALUE"""),85.2777777777777) -> 85.277778 | K11: FALSE | L11: =IF(K11=TRUE(),0,IF(C11="x",IF(ISBLANK(A11),"", I11*(J11/100)),"PENDENTE")) -> 170.55556 | O11: =IFERROR(__xludf.DUMMYFUNCTION("""COMPUTED_VALUE"""),"x") -> x | P11: =IFERROR(__xludf.DUMMYFUNCTION("""COMPUTED_VALUE"""),"x") -> x | T11: =IFERROR(__xludf.DUMMYFUNCTION("""COMPUTED_VALUE"""),"x") -> x | Z11: x | AA11: x | AB11: =COUNTA(M11:Y11) -> 3 | AC11: =IF(M11="x",M$1000*1,"")*BY11 -> #VALUE! | AD11: =IF(N11="x",N$1000*1,"")*BZ11 -> #VALUE! | AE11: =IF(O11="x",O$1000*1,"")*CA11 -> 1 | AF11: =IF(P11="x",P$1000*1,"")*CB11 -> 1.2 | AG11: =IF(Q11="x",Q$1000*1,"")*CC11 -> #VALUE! | AH11: =IF(R11="x",R$1000*1,"")*CD11 -> #VALUE! | AI11: =IF(S11="x",S$1000*1,"")*CE11 -> #VALUE! | AJ11: =IF(T11="x",T$1000*1,"")*CF11 -> 1 | ... AQ11: =IF(AA11="x",AA$1000*1,"")*CM11 -> 0 | AR11: =SUM(AC11:AQ11) -> #VALUE! | AS11: =IFERROR(L11/AR11,"") | AT11: =IFERROR(__xludf.DUMMYFUNCTION("""COMPUTED_VALUE"""),"") | AU11: =IFERROR(__xludf.DUMMYFUNCTION("""COMPUTED_VALUE"""),10) -> 10 | AV11: =IFERROR(__xludf.DUMMYFUNCTION("""COMPUTED_VALUE"""),10) -> 10 | AW11: =IFERROR(__xludf.DUMMYFUNCTION("""COMPUTED_VALUE"""),10) -> 10 | AX11: =IFERROR(__xludf.DUMMYFUNCTION("""COMPUTED_VALUE"""),10) -> 10 | AY11: =IFERROR(__xludf.DUMMYFUNCTION("""COMPUTED_VALUE"""),"") | AZ11: =IFERROR(__xludf.DUMMYFUNCTION("""COMPUTED_VALUE"""),"") | BA11: =IFERROR(__xludf.DUMMYFUNCTION("""COMPUTED_VALUE"""),10) -> 10 | BB11: =IFERROR(__xludf.DUMMYFUNCTION("""COMPUTED_VALUE"""),"") | BC11: =IFERROR(__xludf.DUMMYFUNCTION("""COMPUTED_VALUE"""),"") | BD11: =IFERROR(__xludf.DUMMYFUNCTION("""COMPUTED_VALUE"""),"") | BF11: =IFERROR(__xludf.DUMMYFUNCTION("""COMPUTED_VALUE"""),"") | BG11: =IFERROR(__xludf.DUMMYFUNCTION("""COMPUTED_VALUE"""),10) -> 10 | BH11: =IFERROR(__xludf.DUMMYFUNCTION("""COMPUTED_VALUE"""),10) -> 10 | BI11: =IF(AC11=0,"",AC11*$AS11*(AT11/10)) -> #VALUE! | BJ11: =IF(AD11=0,"",AD11*$AS11*(AU11/10)) -> #VALUE! | BK11: =IF(AE11=0,"",AE11*$AS11*(AV11/10)) -> #VALUE! | BL11: =IF(AF11=0,"",AF11*$AS11*(AW11/10)) -> #VALUE! | BM11: =IF(AG11=0,"",AG11*$AS11*(AX11/10)) -> #VALUE! | BN11: =IF(AH11=0,"",AH11*$AS11*(AY11/10)) -> #VALUE! | BO11: =IF(AI11=0,"",AI11*$AS11*(AZ11/10)) -> #VALUE! | BP11: =IF(AJ11=0,"",AJ11*$AS11*(BA11/10)) -> #VALUE! | ... BW11: =IF(AQ11=0,"",AQ11*$AS11*(BH11/10)) | BX11: =SUM(BI11:BW11) -> #VALUE! | BY11: =IF(M11="x","1","") | BZ11: =IF(N11="x","1","") | CA11: =IF(O11="x","1","") -> 1 | CB11: =IF(P11="x","1","") -> 1 | CC11: =IF(Q11="x","1","") | CD11: =IF(R11="x","1","") | CE11: =IF(S11="x","1","") | CF11: =IF(T11="x","1","") -> 1 | ... CH11: =IF(V11="x","1","")
A12: =IFERROR(__xludf.DUMMYFUNCTION("""COMPUTED_VALUE"""),"P780") -> P780 | B12: =IFERROR(__xludf.DUMMYFUNCTION("""COMPUTED_VALUE"""),"Marcos Roberto de Assis") -> Marcos Roberto de Assis | C12: x | D12: =IFERROR(__xludf.DUMMYFUNCTION("""COMPUTED_VALUE"""),45693) -> 45693 | E12: =IF(ISBLANK(D12),"",TEXT(D12,"MMMM")) -> fevereiro | F12: =IFERROR(__xludf.DUMMYFUNCTION("""COMPUTED_VALUE"""),10) -> 10 | G12: =IFERROR(__xludf.DUMMYFUNCTION("""COMPUTED_VALUE"""),600) -> 600 | H12: =IF(ISBLANK(G12),"",F12*G12/1000) -> 6 | I12: =IF(ISBLANK(F12),"",IF(H12<5,200,IF(H12<10,300,IF(H12<20,500,IF(H12<30,750,IF(H12<50,1000,IF(H12<75,1500,IF(H12>75,2000)))))))) -> 300 | J12: =IFERROR(__xludf.DUMMYFUNCTION("""COMPUTED_VALUE"""),99.6543209876543) -> 99.654321 | K12: FALSE | L12: =IF(K12=TRUE(),0,IF(C12="x",IF(ISBLANK(A12),"", I12*(J12/100)),"PENDENTE")) -> 298.96296 | M12: =IFERROR(__xludf.DUMMYFUNCTION("""COMPUTED_VALUE"""),"x") -> x | Q12: =IFERROR(__xludf.DUMMYFUNCTION("""COMPUTED_VALUE"""),"x") -> x | R12: =IFERROR(__xludf.DUMMYFUNCTION("""COMPUTED_VALUE"""),"x") -> x | S12: =IFERROR(__xludf.DUMMYFUNCTION("""COMPUTED_VALUE"""),"x") -> x | Z12: x | AA12: x | AB12: =COUNTA(M12:Y12) -> 4 | AC12: =IF(M12="x",M$1000*1,"")*BY12 -> 1.2 | AD12: =IF(N12="x",N$1000*1,"")*BZ12 -> #VALUE! | AE12: =IF(O12="x",O$1000*1,"")*CA12 -> #VALUE! | AF12: =IF(P12="x",P$1000*1,"")*CB12 -> #VALUE! | AG12: =IF(Q12="x",Q$1000*1,"")*CC12 -> 1 | AH12: =IF(R12="x",R$1000*1,"")*CD12 -> 1 | AI12: =IF(S12="x",S$1000*1,"")*CE12 -> 1.1 | AJ12: =IF(T12="x",T$1000*1,"")*CF12 -> #VALUE! | ... AQ12: =IF(AA12="x",AA$1000*1,"")*CM12 -> 0 | AR12: =SUM(AC12:AQ12) -> #VALUE! | AS12: =IFERROR(L12/AR12,"") | AT12: =IFERROR(__xludf.DUMMYFUNCTION("""COMPUTED_VALUE"""),10) -> 10 | AU12: =IFERROR(__xludf.DUMMYFUNCTION("""COMPUTED_VALUE"""),"") | AV12: =IFERROR(__xludf.DUMMYFUNCTION("""COMPUTED_VALUE"""),"") | AW12: =IFERROR(__xludf.DUMMYFUNCTION("""COMPUTED_VALUE"""),"") | AX12: =IFERROR(__xludf.DUMMYFUNCTION("""COMPUTED_VALUE"""),10) -> 10 | AY12: =IFERROR(__xludf.DUMMYFUNCTION("""COMPUTED_VALUE"""),10) -> 10 | AZ12: =IFERROR(__xludf.DUMMYFUNCTION("""COMPUTED_VALUE"""),10) -> 10 | BA12: =IFERROR(__xludf.DUMMYFUNCTION("""COMPUTED_VALUE"""),"") | BB12: =IFERROR(__xludf.DUMMYFUNCTION("""COMPUTED_VALUE"""),"") | BC12: =IFERROR(__xludf.DUMMYFUNCTION("""COMPUTED_VALUE"""),"") | BD12: =IFERROR(__xludf.DUMMYFUNCTION("""COMPUTED_VALUE"""),"") | BF12: =IFERROR(__xludf.DUMMYFUNCTION("""COMPUTED_VALUE"""),"") | BG12: =IFERROR(__xludf.DUMMYFUNCTION("""COMPUTED_VALUE"""),10) -> 10 | BH12: =IFERROR(__xludf.DUMMYFUNCTION("""COMPUTED_VALUE"""),10) -> 10 | BI12: =IF(AC12=0,"",AC12*$AS12*(AT12/10)) -> #VALUE! | BJ12: =IF(AD12=0,"",AD12*$AS12*(AU12/10)) -> #VALUE! | BK12: =IF(AE12=0,"",AE12*$AS12*(AV12/10)) -> #VALUE! | BL12: =IF(AF12=0,"",AF12*$AS12*(AW12/10)) -> #VALUE! | BM12: =IF(AG12=0,"",AG12*$AS12*(AX12/10)) -> #VALUE! | BN12: =IF(AH12=0,"",AH12*$AS12*(AY12/10)) -> #VALUE! | BO12: =IF(AI12=0,"",AI12*$AS12*(AZ12/10)) -> #VALUE! | BP12: =IF(AJ12=0,"",AJ12*$AS12*(BA12/10)) -> #VALUE! | ... BW12: =IF(AQ12=0,"",AQ12*$AS12*(BH12/10)) | BX12: =SUM(BI12:BW12) -> #VALUE! | BY12: =IF(M12="x","1","") -> 1 | BZ12: =IF(N12="x","1","") | CA12: =IF(O12="x","1","") | CB12: =IF(P12="x","1","") | CC12: =IF(Q12="x","1","") -> 1 | CD12: =IF(R12="x","1","") -> 1 | CE12: =IF(S12="x","1","") -> 1 | CF12: =IF(T12="x","1","") | ... CH12: =IF(V12="x","1","")
A13: =IFERROR(__xludf.DUMMYFUNCTION("""COMPUTED_VALUE"""),"P776") -> P776 | B13: =IFERROR(__xludf.DUMMYFUNCTION("""COMPUTED_VALUE"""),"Álvaro Afonso Domingues") -> Álvaro Afonso Domingues | C13: x | D13: =IFERROR(__xludf.DUMMYFUNCTION("""COMPUTED_VALUE"""),45671) -> 45671 | E13: =IF(ISBLANK(D13),"",TEXT(D13,"MMMM")) -> janeiro | F13: =IFERROR(__xludf.DUMMYFUNCTION("""COMPUTED_VALUE"""),8) -> 8 | G13: =IFERROR(__xludf.DUMMYFUNCTION("""COMPUTED_VALUE"""),600) -> 600 | H13: =IF(ISBLANK(G13),"",F13*G13/1000) -> 4.8 | I13: =IF(ISBLANK(F13),"",IF(H13<5,200,IF(H13<10,300,IF(H13<20,500,IF(H13<30,750,IF(H13<50,1000,IF(H13<75,1500,IF(H13>75,2000)))))))) -> 200 | J13: =IFERROR(__xludf.DUMMYFUNCTION("""COMPUTED_VALUE"""),96.6666666666666) -> 96.666667 | K13: FALSE | L13: =IF(K13=TRUE(),0,IF(C13="x",IF(ISBLANK(A13),"", I13*(J13/100)),"PENDENTE")) -> 193.33333 | M13: =IFERROR(__xludf.DUMMYFUNCTION("""COMPUTED_VALUE"""),"x") -> x | Q13: =IFERROR(__xludf.DUMMYFUNCTION("""COMPUTED_VALUE"""),"x") -> x | R13: =IFERROR(__xludf.DUMMYFUNCTION("""COMPUTED_VALUE"""),"x") -> x | S13: =IFERROR(__xludf.DUMMYFUNCTION("""COMPUTED_VALUE"""),"x") -> x | Z13: x | AA13: x | AB13: =COUNTA(M13:Y13) -> 4 | AC13: =IF(M13="x",M$1000*1,"")*BY13 -> 1.2 | AD13: =IF(N13="x",N$1000*1,"")*BZ13 -> #VALUE! | AE13: =IF(O13="x",O$1000*1,"")*CA13 -> #VALUE! | AF13: =IF(P13="x",P$1000*1,"")*CB13 -> #VALUE! | AG13: =IF(Q13="x",Q$1000*1,"")*CC13 -> 1 | AH13: =IF(R13="x",R$1000*1,"")*CD13 -> 1 | AI13: =IF(S13="x",S$1000*1,"")*CE13 -> 1.1 | AJ13: =IF(T13="x",T$1000*1,"")*CF13 -> #VALUE! | ... AQ13: =IF(AA13="x",AA$1000*1,"")*CM13 -> 0 | AR13: =SUM(AC13:AQ13) -> #VALUE! | AS13: =IFERROR(L13/AR13,"") | AT13: =IFERROR(__xludf.DUMMYFUNCTION("""COMPUTED_VALUE"""),10) -> 10 | AU13: =IFERROR(__xludf.DUMMYFUNCTION("""COMPUTED_VALUE"""),"") | AV13: =IFERROR(__xludf.DUMMYFUNCTION("""COMPUTED_VALUE"""),"") | AW13: =IFERROR(__xludf.DUMMYFUNCTION("""COMPUTED_VALUE"""),"") | AX13: =IFERROR(__xludf.DUMMYFUNCTION("""COMPUTED_VALUE"""),10) -> 10 | AY13: =IFERROR(__xludf.DUMMYFUNCTION("""COMPUTED_VALUE"""),10) -> 10 | AZ13: =IFERROR(__xludf.DUMMYFUNCTION("""COMPUTED_VALUE"""),10) -> 10 | BA13: =IFERROR(__xludf.DUMMYFUNCTION("""COMPUTED_VALUE"""),"") | BB13: =IFERROR(__xludf.DUMMYFUNCTION("""COMPUTED_VALUE"""),"") | BC13: =IFERROR(__xludf.DUMMYFUNCTION("""COMPUTED_VALUE"""),"") | BD13: =IFERROR(__xludf.DUMMYFUNCTION("""COMPUTED_VALUE"""),"") | BF13: =IFERROR(__xludf.DUMMYFUNCTION("""COMPUTED_VALUE"""),"") | BG13: =IFERROR(__xludf.DUMMYFUNCTION("""COMPUTED_VALUE"""),10) -> 10 | BH13: =IFERROR(__xludf.DUMMYFUNCTION("""COMPUTED_VALUE"""),10) -> 10 | BI13: =IF(AC13=0,"",AC13*$AS13*(AT13/10)) -> #VALUE! | BJ13: =IF(AD13=0,"",AD13*$AS13*(AU13/10)) -> #VALUE! | BK13: =IF(AE13=0,"",AE13*$AS13*(AV13/10)) -> #VALUE! | BL13: =IF(AF13=0,"",AF13*$AS13*(AW13/10)) -> #VALUE! | BM13: =IF(AG13=0,"",AG13*$AS13*(AX13/10)) -> #VALUE! | BN13: =IF(AH13=0,"",AH13*$AS13*(AY13/10)) -> #VALUE! | BO13: =IF(AI13=0,"",AI13*$AS13*(AZ13/10)) -> #VALUE! | BP13: =IF(AJ13=0,"",AJ13*$AS13*(BA13/10)) -> #VALUE! | ... BW13: =IF(AQ13=0,"",AQ13*$AS13*(BH13/10)) | BX13: =SUM(BI13:BW13) -> #VALUE! | BY13: =IF(M13="x","1","") -> 1 | BZ13: =IF(N13="x","1","") | CA13: =IF(O13="x","1","") | CB13: =IF(P13="x","1","") | CC13: =IF(Q13="x","1","") -> 1 | CD13: =IF(R13="x","1","") -> 1 | CE13: =IF(S13="x","1","") -> 1 | CF13: =IF(T13="x","1","") | ... CH13: =IF(V13="x","1","")
A14: =IFERROR(__xludf.DUMMYFUNCTION("""COMPUTED_VALUE"""),"P771") -> P771 | B14: =IFERROR(__xludf.DUMMYFUNCTION("""COMPUTED_VALUE"""),"Ailton Sathler ") -> Ailton Sathler | C14: x | D14: =IFERROR(__xludf.DUMMYFUNCTION("""COMPUTED_VALUE"""),45674) -> 45674 | E14: =IF(ISBLANK(D14),"",TEXT(D14,"MMMM")) -> janeiro | F14: =IFERROR(__xludf.DUMMYFUNCTION("""COMPUTED_VALUE"""),14) -> 14 | G14: =IFERROR(__xludf.DUMMYFUNCTION("""COMPUTED_VALUE"""),600) -> 600 | H14: =IF(ISBLANK(G14),"",F14*G14/1000) -> 8.4 | I14: =IF(ISBLANK(F14),"",IF(H14<5,200,IF(H14<10,300,IF(H14<20,500,IF(H14<30,750,IF(H14<50,1000,IF(H14<75,1500,IF(H14>75,2000)))))))) -> 300 | J14: =IFERROR(__xludf.DUMMYFUNCTION("""COMPUTED_VALUE"""),92.4444444444444) -> 92.444444 | K14: FALSE | L14: =IF(K14=TRUE(),0,IF(C14="x",IF(ISBLANK(A14),"", I14*(J14/100)),"PENDENTE")) -> 277.33333 | O14: =IFERROR(__xludf.DUMMYFUNCTION("""COMPUTED_VALUE"""),"x") -> x | P14: =IFERROR(__xludf.DUMMYFUNCTION("""COMPUTED_VALUE"""),"x") -> x | T14: =IFERROR(__xludf.DUMMYFUNCTION("""COMPUTED_VALUE"""),"x") -> x | Z14: x | AA14: x | AB14: =COUNTA(M14:Y14) -> 3 | AC14: =IF(M14="x",M$1000*1,"")*BY14 -> #VALUE! | AD14: =IF(N14="x",N$1000*1,"")*BZ14 -> #VALUE! | AE14: =IF(O14="x",O$1000*1,"")*CA14 -> 1 | AF14: =IF(P14="x",P$1000*1,"")*CB14 -> 1.2 | AG14: =IF(Q14="x",Q$1000*1,"")*CC14 -> #VALUE! | AH14: =IF(R14="x",R$1000*1,"")*CD14 -> #VALUE! | AI14: =IF(S14="x",S$1000*1,"")*CE14 -> #VALUE! | AJ14: =IF(T14="x",T$1000*1,"")*CF14 -> 1 | ... AQ14: =IF(AA14="x",AA$1000*1,"")*CM14 -> 0 | AR14: =SUM(AC14:AQ14) -> #VALUE! | AS14: =IFERROR(L14/AR14,"") | AT14: =IFERROR(__xludf.DUMMYFUNCTION("""COMPUTED_VALUE"""),"") | AU14: =IFERROR(__xludf.DUMMYFUNCTION("""COMPUTED_VALUE"""),10) -> 10 | AV14: =IFERROR(__xludf.DUMMYFUNCTION("""COMPUTED_VALUE"""),10) -> 10 | AW14: =IFERROR(__xludf.DUMMYFUNCTION("""COMPUTED_VALUE"""),10) -> 10 | AX14: =IFERROR(__xludf.DUMMYFUNCTION("""COMPUTED_VALUE"""),10) -> 10 | AY14: =IFERROR(__xludf.DUMMYFUNCTION("""COMPUTED_VALUE"""),"") | AZ14: =IFERROR(__xludf.DUMMYFUNCTION("""COMPUTED_VALUE"""),"") | BA14: =IFERROR(__xludf.DUMMYFUNCTION("""COMPUTED_VALUE"""),9.5) -> 9.5 | BB14: =IFERROR(__xludf.DUMMYFUNCTION("""COMPUTED_VALUE"""),"") | BC14: =IFERROR(__xludf.DUMMYFUNCTION("""COMPUTED_VALUE"""),"") | BD14: =IFERROR(__xludf.DUMMYFUNCTION("""COMPUTED_VALUE"""),"") | BF14: =IFERROR(__xludf.DUMMYFUNCTION("""COMPUTED_VALUE"""),"") | BG14: =IFERROR(__xludf.DUMMYFUNCTION("""COMPUTED_VALUE"""),9.66666666666666) -> 9.6666667 | BH14: =IFERROR(__xludf.DUMMYFUNCTION("""COMPUTED_VALUE"""),10) -> 10 | BI14: =IF(AC14=0,"",AC14*$AS14*(AT14/10)) -> #VALUE! | BJ14: =IF(AD14=0,"",AD14*$AS14*(AU14/10)) -> #VALUE! | BK14: =IF(AE14=0,"",AE14*$AS14*(AV14/10)) -> #VALUE! | BL14: =IF(AF14=0,"",AF14*$AS14*(AW14/10)) -> #VALUE! | BM14: =IF(AG14=0,"",AG14*$AS14*(AX14/10)) -> #VALUE! | BN14: =IF(AH14=0,"",AH14*$AS14*(AY14/10)) -> #VALUE! | BO14: =IF(AI14=0,"",AI14*$AS14*(AZ14/10)) -> #VALUE! | BP14: =IF(AJ14=0,"",AJ14*$AS14*(BA14/10)) -> #VALUE! | ... BW14: =IF(AQ14=0,"",AQ14*$AS14*(BH14/10)) | BX14: =SUM(BI14:BW14) -> #VALUE! | BY14: =IF(M14="x","1","") | BZ14: =IF(N14="x","1","") | CA14: =IF(O14="x","1","") -> 1 | CB14: =IF(P14="x","1","") -> 1 | CC14: =IF(Q14="x","1","") | CD14: =IF(R14="x","1","") | CE14: =IF(S14="x","1","") | CF14: =IF(T14="x","1","") -> 1 | ... CH14: =IF(V14="x","1","")
A15: =IFERROR(__xludf.DUMMYFUNCTION("""COMPUTED_VALUE"""),"P766") -> P766 | B15: =IFERROR(__xludf.DUMMYFUNCTION("""COMPUTED_VALUE"""),"Auto Máquinas (Vinícius)") -> Auto Máquinas (Vinícius) | C15: x | D15: =IFERROR(__xludf.DUMMYFUNCTION("""COMPUTED_VALUE"""),45665) -> 45665 | E15: =IF(ISBLANK(D15),"",TEXT(D15,"MMMM")) -> janeiro | F15: =IFERROR(__xludf.DUMMYFUNCTION("""COMPUTED_VALUE"""),16) -> 16 | G15: =IFERROR(__xludf.DUMMYFUNCTION("""COMPUTED_VALUE"""),600) -> 600 | H15: =IF(ISBLANK(G15),"",F15*G15/1000) -> 9.6 | I15: =IF(ISBLANK(F15),"",IF(H15<5,200,IF(H15<10,300,IF(H15<20,500,IF(H15<30,750,IF(H15<50,1000,IF(H15<75,1500,IF(H15>75,2000)))))))) -> 300 | J15: =IFERROR(__xludf.DUMMYFUNCTION("""COMPUTED_VALUE"""),92.4444444444444) -> 92.444444 | K15: FALSE | L15: =IF(K15=TRUE(),0,IF(C15="x",IF(ISBLANK(A15),"", I15*(J15/100)),"PENDENTE")) -> 277.33333 | O15: =IFERROR(__xludf.DUMMYFUNCTION("""COMPUTED_VALUE"""),"x") -> x | P15: =IFERROR(__xludf.DUMMYFUNCTION("""COMPUTED_VALUE"""),"x") -> x | T15: =IFERROR(__xludf.DUMMYFUNCTION("""COMPUTED_VALUE"""),"x") -> x | Z15: x | AA15: x | AB15: =COUNTA(M15:Y15) -> 3 | AC15: =IF(M15="x",M$1000*1,"")*BY15 -> #VALUE! | AD15: =IF(N15="x",N$1000*1,"")*BZ15 -> #VALUE! | AE15: =IF(O15="x",O$1000*1,"")*CA15 -> 1 | AF15: =IF(P15="x",P$1000*1,"")*CB15 -> 1.2 | AG15: =IF(Q15="x",Q$1000*1,"")*CC15 -> #VALUE! | AH15: =IF(R15="x",R$1000*1,"")*CD15 -> #VALUE! | AI15: =IF(S15="x",S$1000*1,"")*CE15 -> #VALUE! | AJ15: =IF(T15="x",T$1000*1,"")*CF15 -> 1 | ... AQ15: =IF(AA15="x",AA$1000*1,"")*CM15 -> 0 | AR15: =SUM(AC15:AQ15) -> #VALUE! | AS15: =IFERROR(L15/AR15,"") | AT15: =IFERROR(__xludf.DUMMYFUNCTION("""COMPUTED_VALUE"""),"") | AU15: =IFERROR(__xludf.DUMMYFUNCTION("""COMPUTED_VALUE"""),10) -> 10 | AV15: =IFERROR(__xludf.DUMMYFUNCTION("""COMPUTED_VALUE"""),10) -> 10 | AW15: =IFERROR(__xludf.DUMMYFUNCTION("""COMPUTED_VALUE"""),10) -> 10 | AX15: =IFERROR(__xludf.DUMMYFUNCTION("""COMPUTED_VALUE"""),10) -> 10 | AY15: =IFERROR(__xludf.DUMMYFUNCTION("""COMPUTED_VALUE"""),"") | AZ15: =IFERROR(__xludf.DUMMYFUNCTION("""COMPUTED_VALUE"""),"") | BA15: =IFERROR(__xludf.DUMMYFUNCTION("""COMPUTED_VALUE"""),10) -> 10 | BB15: =IFERROR(__xludf.DUMMYFUNCTION("""COMPUTED_VALUE"""),"") | BC15: =IFERROR(__xludf.DUMMYFUNCTION("""COMPUTED_VALUE"""),"") | BD15: =IFERROR(__xludf.DUMMYFUNCTION("""COMPUTED_VALUE"""),"") | BF15: =IFERROR(__xludf.DUMMYFUNCTION("""COMPUTED_VALUE"""),"") | BG15: =IFERROR(__xludf.DUMMYFUNCTION("""COMPUTED_VALUE"""),10) -> 10 | BH15: =IFERROR(__xludf.DUMMYFUNCTION("""COMPUTED_VALUE"""),10) -> 10 | BI15: =IF(AC15=0,"",AC15*$AS15*(AT15/10)) -> #VALUE! | BJ15: =IF(AD15=0,"",AD15*$AS15*(AU15/10)) -> #VALUE! | BK15: =IF(AE15=0,"",AE15*$AS15*(AV15/10)) -> #VALUE! | BL15: =IF(AF15=0,"",AF15*$AS15*(AW15/10)) -> #VALUE! | BM15: =IF(AG15=0,"",AG15*$AS15*(AX15/10)) -> #VALUE! | BN15: =IF(AH15=0,"",AH15*$AS15*(AY15/10)) -> #VALUE! | BO15: =IF(AI15=0,"",AI15*$AS15*(AZ15/10)) -> #VALUE! | BP15: =IF(AJ15=0,"",AJ15*$AS15*(BA15/10)) -> #VALUE! | ... BW15: =IF(AQ15=0,"",AQ15*$AS15*(BH15/10)) | BX15: =SUM(BI15:BW15) -> #VALUE! | BY15: =IF(M15="x","1","") | BZ15: =IF(N15="x","1","") | CA15: =IF(O15="x","1","") -> 1 | CB15: =IF(P15="x","1","") -> 1 | CC15: =IF(Q15="x","1","") | CD15: =IF(R15="x","1","") | CE15: =IF(S15="x","1","") | CF15: =IF(T15="x","1","") -> 1 | ... CH15: =IF(V15="x","1","")
A16: =IFERROR(__xludf.DUMMYFUNCTION("""COMPUTED_VALUE"""),"P765") -> P765 | B16: =IFERROR(__xludf.DUMMYFUNCTION("""COMPUTED_VALUE"""),"Silviana Malaquias da Silva") -> Silviana Malaquias da Silva | C16: x | D16: =IFERROR(__xludf.DUMMYFUNCTION("""COMPUTED_VALUE"""),45666) -> 45666 | E16: =IF(ISBLANK(D16),"",TEXT(D16,"MMMM")) -> janeiro | F16: =IFERROR(__xludf.DUMMYFUNCTION("""COMPUTED_VALUE"""),13) -> 13 | G16: =IFERROR(__xludf.DUMMYFUNCTION("""COMPUTED_VALUE"""),585) -> 585 | H16: =IF(ISBLANK(G16),"",F16*G16/1000) -> 7.605 | I16: =IF(ISBLANK(F16),"",IF(H16<5,200,IF(H16<10,300,IF(H16<20,500,IF(H16<30,750,IF(H16<50,1000,IF(H16<75,1500,IF(H16>75,2000)))))))) -> 300 | J16: =IFERROR(__xludf.DUMMYFUNCTION("""COMPUTED_VALUE"""),95.7777777777777) -> 95.777778 | K16: FALSE | L16: =IF(K16=TRUE(),0,IF(C16="x",IF(ISBLANK(A16),"", I16*(J16/100)),"PENDENTE")) -> 287.33333 | R16: =IFERROR(__xludf.DUMMYFUNCTION("""COMPUTED_VALUE"""),"x") -> x | S16: =IFERROR(__xludf.DUMMYFUNCTION("""COMPUTED_VALUE"""),"x") -> x | Z16: x | AA16: x | AB16: =COUNTA(M16:Y16) -> 2 | AC16: =IF(M16="x",M$1000*1,"")*BY16 -> #VALUE! | AD16: =IF(N16="x",N$1000*1,"")*BZ16 -> #VALUE! | AE16: =IF(O16="x",O$1000*1,"")*CA16 -> #VALUE! | AF16: =IF(P16="x",P$1000*1,"")*CB16 -> #VALUE! | AG16: =IF(Q16="x",Q$1000*1,"")*CC16 -> #VALUE! | AH16: =IF(R16="x",R$1000*1,"")*CD16 -> 1 | AI16: =IF(S16="x",S$1000*1,"")*CE16 -> 1.1 | AJ16: =IF(T16="x",T$1000*1,"")*CF16 -> #VALUE! | ... AQ16: =IF(AA16="x",AA$1000*1,"")*CM16 -> 0 | AR16: =SUM(AC16:AQ16) -> #VALUE! | AS16: =IFERROR(L16/AR16,"") | AT16: =IFERROR(__xludf.DUMMYFUNCTION("""COMPUTED_VALUE"""),"") | AU16: =IFERROR(__xludf.DUMMYFUNCTION("""COMPUTED_VALUE"""),"") | AV16: =IFERROR(__xludf.DUMMYFUNCTION("""COMPUTED_VALUE"""),"") | AW16: =IFERROR(__xludf.DUMMYFUNCTION("""COMPUTED_VALUE"""),"") | AX16: =IFERROR(__xludf.DUMMYFUNCTION("""COMPUTED_VALUE"""),"") | AY16: =IFERROR(__xludf.DUMMYFUNCTION("""COMPUTED_VALUE"""),10) -> 10 | AZ16: =IFERROR(__xludf.DUMMYFUNCTION("""COMPUTED_VALUE"""),10) -> 10 | BA16: =IFERROR(__xludf.DUMMYFUNCTION("""COMPUTED_VALUE"""),"") | BB16: =IFERROR(__xludf.DUMMYFUNCTION("""COMPUTED_VALUE"""),"") | BC16: =IFERROR(__xludf.DUMMYFUNCTION("""COMPUTED_VALUE"""),"") | BD16: =IFERROR(__xludf.DUMMYFUNCTION("""COMPUTED_VALUE"""),"") | BF16: =IFERROR(__xludf.DUMMYFUNCTION("""COMPUTED_VALUE"""),"") | BG16: =IFERROR(__xludf.DUMMYFUNCTION("""COMPUTED_VALUE"""),10) -> 10 | BH16: =IFERROR(__xludf.DUMMYFUNCTION("""COMPUTED_VALUE"""),10) -> 10 | BI16: =IF(AC16=0,"",AC16*$AS16*(AT16/10)) -> #VALUE! | BJ16: =IF(AD16=0,"",AD16*$AS16*(AU16/10)) -> #VALUE! | BK16: =IF(AE16=0,"",AE16*$AS16*(AV16/10)) -> #VALUE! | BL16: =IF(AF16=0,"",AF16*$AS16*(AW16/10)) -> #VALUE! | BM16: =IF(AG16=0,"",AG16*$AS16*(AX16/10)) -> #VALUE! | BN16: =IF(AH16=0,"",AH16*$AS16*(AY16/10)) -> #VALUE! | BO16: =IF(AI16=0,"",AI16*$AS16*(AZ16/10)) -> #VALUE! | BP16: =IF(AJ16=0,"",AJ16*$AS16*(BA16/10)) -> #VALUE! | ... BW16: =IF(AQ16=0,"",AQ16*$AS16*(BH16/10)) | BX16: =SUM(BI16:BW16) -> #VALUE! | BY16: =IF(M16="x","1","") | BZ16: =IF(N16="x","1","") | CA16: =IF(O16="x","1","") | CB16: =IF(P16="x","1","") | CC16: =IF(Q16="x","1","") | CD16: =IF(R16="x","1","") -> 1 | CE16: =IF(S16="x","1","") -> 1 | CF16: =IF(T16="x","1","") | ... CH16: =IF(V16="x","1","")
A17: =IFERROR(__xludf.DUMMYFUNCTION("""COMPUTED_VALUE"""),"P768") -> P768 | B17: =IFERROR(__xludf.DUMMYFUNCTION("""COMPUTED_VALUE"""),"Ronaldo José da Silva") -> Ronaldo José da Silva | C17: x | D17: =IFERROR(__xludf.DUMMYFUNCTION("""COMPUTED_VALUE"""),45666) -> 45666 | E17: =IF(ISBLANK(D17),"",TEXT(D17,"MMMM")) -> janeiro | F17: =IFERROR(__xludf.DUMMYFUNCTION("""COMPUTED_VALUE"""),16) -> 16 | G17: =IFERROR(__xludf.DUMMYFUNCTION("""COMPUTED_VALUE"""),600) -> 600 | H17: =IF(ISBLANK(G17),"",F17*G17/1000) -> 9.6 | I17: =IF(ISBLANK(F17),"",IF(H17<5,200,IF(H17<10,300,IF(H17<20,500,IF(H17<30,750,IF(H17<50,1000,IF(H17<75,1500,IF(H17>75,2000)))))))) -> 300 | J17: =IFERROR(__xludf.DUMMYFUNCTION("""COMPUTED_VALUE"""),83.25) -> 83.25 | K17: FALSE | L17: =IF(K17=TRUE(),0,IF(C17="x",IF(ISBLANK(A17),"", I17*(J17/100)),"PENDENTE")) -> 249.75 | M17: =IFERROR(__xludf.DUMMYFUNCTION("""COMPUTED_VALUE"""),"x") -> x | O17: =IFERROR(__xludf.DUMMYFUNCTION("""COMPUTED_VALUE"""),"x") -> x | P17: =IFERROR(__xludf.DUMMYFUNCTION("""COMPUTED_VALUE"""),"x") -> x | Q17: =IFERROR(__xludf.DUMMYFUNCTION("""COMPUTED_VALUE"""),"x") -> x | R17: =IFERROR(__xludf.DUMMYFUNCTION("""COMPUTED_VALUE"""),"x") -> x | S17: =IFERROR(__xludf.DUMMYFUNCTION("""COMPUTED_VALUE"""),"x") -> x | T17: =IFERROR(__xludf.DUMMYFUNCTION("""COMPUTED_VALUE"""),"x") -> x | Z17: x | AA17: x | AB17: =COUNTA(M17:Y17) -> 7 | AC17: =IF(M17="x",M$1000*1,"")*BY17 -> 1.2 | AD17: =IF(N17="x",N$1000*1,"")*BZ17 -> #VALUE! | AE17: =IF(O17="x",O$1000*1,"")*CA17 -> 1 | AF17: =IF(P17="x",P$1000*1,"")*CB17 -> 1.2 | AG17: =IF(Q17="x",Q$1000*1,"")*CC17 -> 1 | AH17: =IF(R17="x",R$1000*1,"")*CD17 -> 1 | AI17: =IF(S17="x",S$1000*1,"")*CE17 -> 1.1 | AJ17: =IF(T17="x",T$1000*1,"")*CF17 -> 1 | ... AQ17: =IF(AA17="x",AA$1000*1,"")*CM17 -> 0 | AR17: =SUM(AC17:AQ17) -> #VALUE! | AS17: =IFERROR(L17/AR17,"") | AT17: =IFERROR(__xludf.DUMMYFUNCTION("""COMPUTED_VALUE"""),9.6) -> 9.6 | AU17: =IFERROR(__xludf.DUMMYFUNCTION("""COMPUTED_VALUE"""),9.33333333333333) -> 9.3333333 | AV17: =IFERROR(__xludf.DUMMYFUNCTION("""COMPUTED_VALUE"""),9.66666666666666) -> 9.6666667 | AW17: =IFERROR(__xludf.DUMMYFUNCTION("""COMPUTED_VALUE"""),9.66666666666666) -> 9.6666667 | AX17: =IFERROR(__xludf.DUMMYFUNCTION("""COMPUTED_VALUE"""),9.66666666666666) -> 9.6666667 | AY17: =IFERROR(__xludf.DUMMYFUNCTION("""COMPUTED_VALUE"""),9.83333333333333) -> 9.8333333 | AZ17: =IFERROR(__xludf.DUMMYFUNCTION("""COMPUTED_VALUE"""),9.66666666666666) -> 9.6666667 | BA17: =IFERROR(__xludf.DUMMYFUNCTION("""COMPUTED_VALUE"""),9) -> 9 | BB17: =IFERROR(__xludf.DUMMYFUNCTION("""COMPUTED_VALUE"""),"") | BC17: =IFERROR(__xludf.DUMMYFUNCTION("""COMPUTED_VALUE"""),"") | BD17: =IFERROR(__xludf.DUMMYFUNCTION("""COMPUTED_VALUE"""),"") | BF17: =IFERROR(__xludf.DUMMYFUNCTION("""COMPUTED_VALUE"""),"") | BG17: =IFERROR(__xludf.DUMMYFUNCTION("""COMPUTED_VALUE"""),10) -> 10 | BH17: =IFERROR(__xludf.DUMMYFUNCTION("""COMPUTED_VALUE"""),10) -> 10 | BI17: =IF(AC17=0,"",AC17*$AS17*(AT17/10)) -> #VALUE! | BJ17: =IF(AD17=0,"",AD17*$AS17*(AU17/10)) -> #VALUE! | BK17: =IF(AE17=0,"",AE17*$AS17*(AV17/10)) -> #VALUE! | BL17: =IF(AF17=0,"",AF17*$AS17*(AW17/10)) -> #VALUE! | BM17: =IF(AG17=0,"",AG17*$AS17*(AX17/10)) -> #VALUE! | BN17: =IF(AH17=0,"",AH17*$AS17*(AY17/10)) -> #VALUE! | BO17: =IF(AI17=0,"",AI17*$AS17*(AZ17/10)) -> #VALUE! | BP17: =IF(AJ17=0,"",AJ17*$AS17*(BA17/10)) -> #VALUE! | ... BW17: =IF(AQ17=0,"",AQ17*$AS17*(BH17/10)) | BX17: =SUM(BI17:BW17) -> #VALUE! | BY17: =IF(M17="x","1","") -> 1 | BZ17: =IF(N17="x","1","") | CA17: =IF(O17="x","1","") -> 1 | CB17: =IF(P17="x","1","") -> 1 | CC17: =IF(Q17="x","1","") -> 1 | CD17: =IF(R17="x","1","") -> 1 | CE17: =IF(S17="x","1","") -> 1 | CF17: =IF(T17="x","1","") -> 1 | ... CH17: =IF(V17="x","1","")
